[2024-06-17T15:05:02.668+0000] {local_task_job_runner.py:120} INFO - ::group::Pre task execution logs
[2024-06-17T15:05:02.704+0000] {taskinstance.py:2076} INFO - Dependencies all met for dep_context=non-requeueable deps ti=<TaskInstance: alerting_skipped.check_status scheduled__2024-06-17T15:00:00+00:00 [queued]>
[2024-06-17T15:05:02.720+0000] {taskinstance.py:2076} INFO - Dependencies all met for dep_context=requeueable deps ti=<TaskInstance: alerting_skipped.check_status scheduled__2024-06-17T15:00:00+00:00 [queued]>
[2024-06-17T15:05:02.720+0000] {taskinstance.py:2306} INFO - Starting attempt 1 of 6
[2024-06-17T15:05:02.744+0000] {taskinstance.py:2330} INFO - Executing <Task(PythonOperator): check_status> on 2024-06-17 15:00:00+00:00
[2024-06-17T15:05:02.752+0000] {warnings.py:110} WARNING - /home/***/.local/lib/python3.12/site-packages/***/task/task_runner/standard_task_runner.py:61: DeprecationWarning: This process (pid=6586) is multi-threaded, use of fork() may lead to deadlocks in the child.
  pid = os.fork()

[2024-06-17T15:05:02.753+0000] {standard_task_runner.py:63} INFO - Started process 6587 to run task
[2024-06-17T15:05:02.753+0000] {standard_task_runner.py:90} INFO - Running: ['***', 'tasks', 'run', 'alerting_skipped', 'check_status', 'scheduled__2024-06-17T15:00:00+00:00', '--job-id', '363', '--raw', '--subdir', 'DAGS_FOLDER/alerting_skipped.py', '--cfg-path', '/tmp/tmpm7tug99g']
[2024-06-17T15:05:02.754+0000] {standard_task_runner.py:91} INFO - Job 363: Subtask check_status
[2024-06-17T15:05:02.802+0000] {task_command.py:426} INFO - Running <TaskInstance: alerting_skipped.check_status scheduled__2024-06-17T15:00:00+00:00 [running]> on host 4d71c837c754
[2024-06-17T15:05:02.909+0000] {taskinstance.py:2648} INFO - Exporting env vars: AIRFLOW_CTX_DAG_OWNER='***' AIRFLOW_CTX_DAG_ID='alerting_skipped' AIRFLOW_CTX_TASK_ID='check_status' AIRFLOW_CTX_EXECUTION_DATE='2024-06-17T15:00:00+00:00' AIRFLOW_CTX_TRY_NUMBER='1' AIRFLOW_CTX_DAG_RUN_ID='scheduled__2024-06-17T15:00:00+00:00'
[2024-06-17T15:05:02.909+0000] {taskinstance.py:430} INFO - ::endgroup::
[2024-06-17T15:05:02.933+0000] {taskinstance.py:441} INFO - ::group::Post task execution logs
[2024-06-17T15:05:02.934+0000] {taskinstance.py:2905} ERROR - Task failed with exception
Traceback (most recent call last):
  File "/home/airflow/.local/lib/python3.12/site-packages/urllib3/connection.py", line 198, in _new_conn
    sock = connection.create_connection(
           ^^^^^^^^^^^^^^^^^^^^^^^^^^^^^
  File "/home/airflow/.local/lib/python3.12/site-packages/urllib3/util/connection.py", line 85, in create_connection
    raise err
  File "/home/airflow/.local/lib/python3.12/site-packages/urllib3/util/connection.py", line 73, in create_connection
    sock.connect(sa)
ConnectionRefusedError: [Errno 111] Connection refused

The above exception was the direct cause of the following exception:

Traceback (most recent call last):
  File "/home/airflow/.local/lib/python3.12/site-packages/urllib3/connectionpool.py", line 793, in urlopen
    response = self._make_request(
               ^^^^^^^^^^^^^^^^^^^
  File "/home/airflow/.local/lib/python3.12/site-packages/urllib3/connectionpool.py", line 496, in _make_request
    conn.request(
  File "/home/airflow/.local/lib/python3.12/site-packages/urllib3/connection.py", line 400, in request
    self.endheaders()
  File "/usr/local/lib/python3.12/http/client.py", line 1331, in endheaders
    self._send_output(message_body, encode_chunked=encode_chunked)
  File "/usr/local/lib/python3.12/http/client.py", line 1091, in _send_output
    self.send(msg)
  File "/usr/local/lib/python3.12/http/client.py", line 1035, in send
    self.connect()
  File "/home/airflow/.local/lib/python3.12/site-packages/urllib3/connection.py", line 238, in connect
    self.sock = self._new_conn()
                ^^^^^^^^^^^^^^^^
  File "/home/airflow/.local/lib/python3.12/site-packages/urllib3/connection.py", line 213, in _new_conn
    raise NewConnectionError(
urllib3.exceptions.NewConnectionError: <urllib3.connection.HTTPConnection object at 0x7176664e65d0>: Failed to establish a new connection: [Errno 111] Connection refused

The above exception was the direct cause of the following exception:

Traceback (most recent call last):
  File "/home/airflow/.local/lib/python3.12/site-packages/requests/adapters.py", line 486, in send
    resp = conn.urlopen(
           ^^^^^^^^^^^^^
  File "/home/airflow/.local/lib/python3.12/site-packages/urllib3/connectionpool.py", line 847, in urlopen
    retries = retries.increment(
              ^^^^^^^^^^^^^^^^^^
  File "/home/airflow/.local/lib/python3.12/site-packages/urllib3/util/retry.py", line 515, in increment
    raise MaxRetryError(_pool, url, reason) from reason  # type: ignore[arg-type]
    ^^^^^^^^^^^^^^^^^^^^^^^^^^^^^^^^^^^^^^^^^^^^^^^^^^^
urllib3.exceptions.MaxRetryError: HTTPConnectionPool(host='localhost', port=8080): Max retries exceeded with url: /api/v1/dags/alerting_skipped/dagRuns?limit=3&order_by=-execution_date (Caused by NewConnectionError('<urllib3.connection.HTTPConnection object at 0x7176664e65d0>: Failed to establish a new connection: [Errno 111] Connection refused'))

During handling of the above exception, another exception occurred:

Traceback (most recent call last):
  File "/home/airflow/.local/lib/python3.12/site-packages/airflow/models/taskinstance.py", line 465, in _execute_task
    result = _execute_callable(context=context, **execute_callable_kwargs)
             ^^^^^^^^^^^^^^^^^^^^^^^^^^^^^^^^^^^^^^^^^^^^^^^^^^^^^^^^^^^^^
  File "/home/airflow/.local/lib/python3.12/site-packages/airflow/models/taskinstance.py", line 432, in _execute_callable
    return execute_callable(context=context, **execute_callable_kwargs)
           ^^^^^^^^^^^^^^^^^^^^^^^^^^^^^^^^^^^^^^^^^^^^^^^^^^^^^^^^^^^^
  File "/home/airflow/.local/lib/python3.12/site-packages/airflow/models/baseoperator.py", line 400, in wrapper
    return func(self, *args, **kwargs)
           ^^^^^^^^^^^^^^^^^^^^^^^^^^^
  File "/home/airflow/.local/lib/python3.12/site-packages/airflow/operators/python.py", line 235, in execute
    return_value = self.execute_callable()
                   ^^^^^^^^^^^^^^^^^^^^^^^
  File "/home/airflow/.local/lib/python3.12/site-packages/airflow/operators/python.py", line 252, in execute_callable
    return self.python_callable(*self.op_args, **self.op_kwargs)
           ^^^^^^^^^^^^^^^^^^^^^^^^^^^^^^^^^^^^^^^^^^^^^^^^^^^^^
  File "/opt/airflow/dags/alerting_skipped.py", line 36, in check_last_3runs_status
    response = requests.get(f"{base_url}/dags/{dag_id}/dagRuns?limit=3&order_by=-execution_date")
               ^^^^^^^^^^^^^^^^^^^^^^^^^^^^^^^^^^^^^^^^^^^^^^^^^^^^^^^^^^^^^^^^^^^^^^^^^^^^^^^^^^
  File "/home/airflow/.local/lib/python3.12/site-packages/requests/api.py", line 73, in get
    return request("get", url, params=params, **kwargs)
           ^^^^^^^^^^^^^^^^^^^^^^^^^^^^^^^^^^^^^^^^^^^^
  File "/home/airflow/.local/lib/python3.12/site-packages/requests/api.py", line 59, in request
    return session.request(method=method, url=url, **kwargs)
           ^^^^^^^^^^^^^^^^^^^^^^^^^^^^^^^^^^^^^^^^^^^^^^^^^
  File "/home/airflow/.local/lib/python3.12/site-packages/requests/sessions.py", line 589, in request
    resp = self.send(prep, **send_kwargs)
           ^^^^^^^^^^^^^^^^^^^^^^^^^^^^^^
  File "/home/airflow/.local/lib/python3.12/site-packages/requests/sessions.py", line 703, in send
    r = adapter.send(request, **kwargs)
        ^^^^^^^^^^^^^^^^^^^^^^^^^^^^^^^
  File "/home/airflow/.local/lib/python3.12/site-packages/requests/adapters.py", line 519, in send
    raise ConnectionError(e, request=request)
requests.exceptions.ConnectionError: HTTPConnectionPool(host='localhost', port=8080): Max retries exceeded with url: /api/v1/dags/alerting_skipped/dagRuns?limit=3&order_by=-execution_date (Caused by NewConnectionError('<urllib3.connection.HTTPConnection object at 0x7176664e65d0>: Failed to establish a new connection: [Errno 111] Connection refused'))
[2024-06-17T15:05:02.949+0000] {taskinstance.py:1206} INFO - Marking task as UP_FOR_RETRY. dag_id=alerting_skipped, task_id=check_status, run_id=scheduled__2024-06-17T15:00:00+00:00, execution_date=20240617T150000, start_date=20240617T150502, end_date=20240617T150502
[2024-06-17T15:05:02.965+0000] {standard_task_runner.py:110} ERROR - Failed to execute job 363 for task check_status (HTTPConnectionPool(host='localhost', port=8080): Max retries exceeded with url: /api/v1/dags/alerting_skipped/dagRuns?limit=3&order_by=-execution_date (Caused by NewConnectionError('<urllib3.connection.HTTPConnection object at 0x7176664e65d0>: Failed to establish a new connection: [Errno 111] Connection refused')); 6587)
[2024-06-17T15:05:03.008+0000] {local_task_job_runner.py:240} INFO - Task exited with return code 1
[2024-06-17T15:05:03.039+0000] {taskinstance.py:3498} INFO - 0 downstream tasks scheduled from follow-on schedule check
[2024-06-17T15:05:03.041+0000] {local_task_job_runner.py:222} INFO - ::endgroup::
