[2024-06-17T06:20:50.144+0000] {local_task_job_runner.py:120} INFO - ::group::Pre task execution logs
[2024-06-17T06:20:50.164+0000] {taskinstance.py:2076} INFO - Dependencies all met for dep_context=non-requeueable deps ti=<TaskInstance: airflow_example.get_task_instances manual__2024-06-17T06:20:48.899942+00:00 [queued]>
[2024-06-17T06:20:50.173+0000] {taskinstance.py:2076} INFO - Dependencies all met for dep_context=requeueable deps ti=<TaskInstance: airflow_example.get_task_instances manual__2024-06-17T06:20:48.899942+00:00 [queued]>
[2024-06-17T06:20:50.173+0000] {taskinstance.py:2306} INFO - Starting attempt 1 of 6
[2024-06-17T06:20:50.187+0000] {taskinstance.py:2330} INFO - Executing <Task(PythonOperator): get_task_instances> on 2024-06-17 06:20:48.899942+00:00
[2024-06-17T06:20:50.192+0000] {warnings.py:110} WARNING - /home/***/.local/lib/python3.12/site-packages/***/task/task_runner/standard_task_runner.py:61: DeprecationWarning: This process (pid=6313) is multi-threaded, use of fork() may lead to deadlocks in the child.
  pid = os.fork()

[2024-06-17T06:20:50.193+0000] {standard_task_runner.py:63} INFO - Started process 6314 to run task
[2024-06-17T06:20:50.193+0000] {standard_task_runner.py:90} INFO - Running: ['***', 'tasks', 'run', '***_example', 'get_task_instances', 'manual__2024-06-17T06:20:48.899942+00:00', '--job-id', '294', '--raw', '--subdir', 'DAGS_FOLDER/file_jsons_to_postgres.py', '--cfg-path', '/tmp/tmpokh7jsci']
[2024-06-17T06:20:50.194+0000] {standard_task_runner.py:91} INFO - Job 294: Subtask get_task_instances
[2024-06-17T06:20:50.232+0000] {task_command.py:426} INFO - Running <TaskInstance: airflow_example.get_task_instances manual__2024-06-17T06:20:48.899942+00:00 [running]> on host 8cc8d7c9eee4
[2024-06-17T06:20:50.319+0000] {taskinstance.py:2648} INFO - Exporting env vars: AIRFLOW_CTX_DAG_OWNER='***' AIRFLOW_CTX_DAG_ID='***_example' AIRFLOW_CTX_TASK_ID='get_task_instances' AIRFLOW_CTX_EXECUTION_DATE='2024-06-17T06:20:48.899942+00:00' AIRFLOW_CTX_TRY_NUMBER='1' AIRFLOW_CTX_DAG_RUN_ID='manual__2024-06-17T06:20:48.899942+00:00'
[2024-06-17T06:20:50.320+0000] {taskinstance.py:430} INFO - ::endgroup::
[2024-06-17T06:20:50.340+0000] {file_jsons_to_postgres.py:145} ERROR - Request failed: HTTPConnectionPool(host='localhost', port=8080): Max retries exceeded with url: /api/v1/dags/***_example/tasks/insert_json/instances?limit=3 (Caused by NewConnectionError('<urllib3.connection.HTTPConnection object at 0x7668e52ae690>: Failed to establish a new connection: [Errno 111] Connection refused'))
[2024-06-17T06:20:50.340+0000] {python.py:237} INFO - Done. Returned value was: None
[2024-06-17T06:20:50.341+0000] {taskinstance.py:441} INFO - ::group::Post task execution logs
[2024-06-17T06:20:50.350+0000] {taskinstance.py:1206} INFO - Marking task as SUCCESS. dag_id=***_example, task_id=get_task_instances, run_id=manual__2024-06-17T06:20:48.899942+00:00, execution_date=20240617T062048, start_date=20240617T062050, end_date=20240617T062050
[2024-06-17T06:20:50.367+0000] {local_task_job_runner.py:240} INFO - Task exited with return code 0
[2024-06-17T06:20:50.382+0000] {taskinstance.py:3498} INFO - 0 downstream tasks scheduled from follow-on schedule check
[2024-06-17T06:20:50.384+0000] {local_task_job_runner.py:222} INFO - ::endgroup::
