[2024-06-19T18:25:01.288+0000] {local_task_job_runner.py:120} INFO - ::group::Pre task execution logs
[2024-06-19T18:25:01.333+0000] {taskinstance.py:2076} INFO - Dependencies all met for dep_context=non-requeueable deps ti=<TaskInstance: create_table.create_table scheduled__2024-06-18T00:00:00+00:00 [queued]>
[2024-06-19T18:25:01.352+0000] {taskinstance.py:2076} INFO - Dependencies all met for dep_context=requeueable deps ti=<TaskInstance: create_table.create_table scheduled__2024-06-18T00:00:00+00:00 [queued]>
[2024-06-19T18:25:01.353+0000] {taskinstance.py:2306} INFO - Starting attempt 3 of 6
[2024-06-19T18:25:01.388+0000] {taskinstance.py:2330} INFO - Executing <Task(PythonOperator): create_table> on 2024-06-18 00:00:00+00:00
[2024-06-19T18:25:01.397+0000] {warnings.py:110} WARNING - /home/***/.local/lib/python3.12/site-packages/***/task/task_runner/standard_task_runner.py:61: DeprecationWarning: This process (pid=1117) is multi-threaded, use of fork() may lead to deadlocks in the child.
  pid = os.fork()

[2024-06-19T18:25:01.400+0000] {standard_task_runner.py:63} INFO - Started process 1122 to run task
[2024-06-19T18:25:01.402+0000] {standard_task_runner.py:90} INFO - Running: ['***', 'tasks', 'run', 'create_table', 'create_table', 'scheduled__2024-06-18T00:00:00+00:00', '--job-id', '1639', '--raw', '--subdir', 'DAGS_FOLDER/create_table.py', '--cfg-path', '/tmp/tmpklu58uzk']
[2024-06-19T18:25:01.404+0000] {standard_task_runner.py:91} INFO - Job 1639: Subtask create_table
[2024-06-19T18:25:01.504+0000] {task_command.py:426} INFO - Running <TaskInstance: create_table.create_table scheduled__2024-06-18T00:00:00+00:00 [running]> on host e66744caf823
[2024-06-19T18:25:01.728+0000] {taskinstance.py:2648} INFO - Exporting env vars: AIRFLOW_CTX_DAG_OWNER='***' AIRFLOW_CTX_DAG_ID='create_table' AIRFLOW_CTX_TASK_ID='create_table' AIRFLOW_CTX_EXECUTION_DATE='2024-06-18T00:00:00+00:00' AIRFLOW_CTX_TRY_NUMBER='3' AIRFLOW_CTX_DAG_RUN_ID='scheduled__2024-06-18T00:00:00+00:00'
[2024-06-19T18:25:01.730+0000] {taskinstance.py:430} INFO - ::endgroup::
[2024-06-19T18:25:01.786+0000] {taskinstance.py:441} INFO - ::group::Post task execution logs
[2024-06-19T18:25:01.802+0000] {taskinstance.py:2905} ERROR - Task failed with exception
Traceback (most recent call last):
  File "/home/airflow/.local/lib/python3.12/site-packages/airflow/models/taskinstance.py", line 465, in _execute_task
    result = _execute_callable(context=context, **execute_callable_kwargs)
             ^^^^^^^^^^^^^^^^^^^^^^^^^^^^^^^^^^^^^^^^^^^^^^^^^^^^^^^^^^^^^
  File "/home/airflow/.local/lib/python3.12/site-packages/airflow/models/taskinstance.py", line 432, in _execute_callable
    return execute_callable(context=context, **execute_callable_kwargs)
           ^^^^^^^^^^^^^^^^^^^^^^^^^^^^^^^^^^^^^^^^^^^^^^^^^^^^^^^^^^^^
  File "/home/airflow/.local/lib/python3.12/site-packages/airflow/models/baseoperator.py", line 400, in wrapper
    return func(self, *args, **kwargs)
           ^^^^^^^^^^^^^^^^^^^^^^^^^^^
  File "/home/airflow/.local/lib/python3.12/site-packages/airflow/operators/python.py", line 235, in execute
    return_value = self.execute_callable()
                   ^^^^^^^^^^^^^^^^^^^^^^^
  File "/home/airflow/.local/lib/python3.12/site-packages/airflow/operators/python.py", line 252, in execute_callable
    return self.python_callable(*self.op_args, **self.op_kwargs)
           ^^^^^^^^^^^^^^^^^^^^^^^^^^^^^^^^^^^^^^^^^^^^^^^^^^^^^
  File "/opt/airflow/dags/create_table.py", line 17, in create_table
    postgres_hook.run(create_table_sql)
  File "/home/airflow/.local/lib/python3.12/site-packages/airflow/providers/common/sql/hooks/sql.py", line 411, in run
    with closing(self.get_conn()) as conn:
                 ^^^^^^^^^^^^^^^
  File "/home/airflow/.local/lib/python3.12/site-packages/airflow/providers/postgres/hooks/postgres.py", line 131, in get_conn
    conn = deepcopy(self.connection or self.get_connection(conn_id))
                                       ^^^^^^^^^^^^^^^^^^^^^^^^^^^^
  File "/home/airflow/.local/lib/python3.12/site-packages/airflow/hooks/base.py", line 83, in get_connection
    conn = Connection.get_connection_from_secrets(conn_id)
           ^^^^^^^^^^^^^^^^^^^^^^^^^^^^^^^^^^^^^^^^^^^^^^^
  File "/home/airflow/.local/lib/python3.12/site-packages/airflow/models/connection.py", line 519, in get_connection_from_secrets
    raise AirflowNotFoundException(f"The conn_id `{conn_id}` isn't defined")
airflow.exceptions.AirflowNotFoundException: The conn_id `postgres_conn` isn't defined
[2024-06-19T18:25:01.811+0000] {taskinstance.py:1206} INFO - Marking task as UP_FOR_RETRY. dag_id=create_table, task_id=create_table, run_id=scheduled__2024-06-18T00:00:00+00:00, execution_date=20240618T000000, start_date=20240619T182501, end_date=20240619T182501
[2024-06-19T18:25:01.843+0000] {standard_task_runner.py:110} ERROR - Failed to execute job 1639 for task create_table (The conn_id `postgres_conn` isn't defined; 1122)
[2024-06-19T18:25:01.899+0000] {local_task_job_runner.py:240} INFO - Task exited with return code 1
[2024-06-19T18:25:01.948+0000] {taskinstance.py:3498} INFO - 0 downstream tasks scheduled from follow-on schedule check
[2024-06-19T18:25:01.951+0000] {local_task_job_runner.py:222} INFO - ::endgroup::
