[2024-06-24T06:02:48.001+0000] {task_context_logger.py:104} ERROR - Executor reports task instance <TaskInstance: demo_dag_for_alerting_final_1.check_previous_run_status manual__2024-06-24T06:00:45.488818+00:00 [queued]> finished (failed) although the task says it's queued. (Info: None) Was the task killed externally?
