[2024-06-27T12:55:05.916+0000] {local_task_job_runner.py:120} INFO - ::group::Pre task execution logs
[2024-06-27T12:55:05.945+0000] {taskinstance.py:2076} INFO - Dependencies all met for dep_context=non-requeueable deps ti=<TaskInstance: demo_dag_for_alerting_apis_final.skipped_due_to_data_unavailability scheduled__2024-06-27T12:54:00+00:00 [queued]>
[2024-06-27T12:55:05.957+0000] {taskinstance.py:2076} INFO - Dependencies all met for dep_context=requeueable deps ti=<TaskInstance: demo_dag_for_alerting_apis_final.skipped_due_to_data_unavailability scheduled__2024-06-27T12:54:00+00:00 [queued]>
[2024-06-27T12:55:05.958+0000] {taskinstance.py:2306} INFO - Starting attempt 1 of 6
[2024-06-27T12:55:05.973+0000] {taskinstance.py:2330} INFO - Executing <Task(PythonOperator): skipped_due_to_data_unavailability> on 2024-06-27 12:54:00+00:00
[2024-06-27T12:55:05.978+0000] {warnings.py:110} WARNING - /home/***/.local/lib/python3.12/site-packages/***/task/task_runner/standard_task_runner.py:61: DeprecationWarning: This process (pid=4593) is multi-threaded, use of fork() may lead to deadlocks in the child.
  pid = os.fork()

[2024-06-27T12:55:05.979+0000] {standard_task_runner.py:63} INFO - Started process 4594 to run task
[2024-06-27T12:55:05.980+0000] {standard_task_runner.py:90} INFO - Running: ['***', 'tasks', 'run', 'demo_dag_for_alerting_apis_final', 'skipped_due_to_data_unavailability', 'scheduled__2024-06-27T12:54:00+00:00', '--job-id', '4721', '--raw', '--subdir', 'DAGS_FOLDER/demo_dag_for_alerting_apis.py', '--cfg-path', '/tmp/tmpix8seucq']
[2024-06-27T12:55:05.981+0000] {standard_task_runner.py:91} INFO - Job 4721: Subtask skipped_due_to_data_unavailability
[2024-06-27T12:55:06.024+0000] {task_command.py:426} INFO - Running <TaskInstance: demo_dag_for_alerting_apis_final.skipped_due_to_data_unavailability scheduled__2024-06-27T12:54:00+00:00 [running]> on host eeacb89bcfc1
[2024-06-27T12:55:06.122+0000] {taskinstance.py:2648} INFO - Exporting env vars: AIRFLOW_CTX_DAG_OWNER='***' AIRFLOW_CTX_DAG_ID='demo_dag_for_alerting_apis_final' AIRFLOW_CTX_TASK_ID='skipped_due_to_data_unavailability' AIRFLOW_CTX_EXECUTION_DATE='2024-06-27T12:54:00+00:00' AIRFLOW_CTX_TRY_NUMBER='1' AIRFLOW_CTX_DAG_RUN_ID='scheduled__2024-06-27T12:54:00+00:00'
[2024-06-27T12:55:06.123+0000] {taskinstance.py:430} INFO - ::endgroup::
[2024-06-27T12:55:06.136+0000] {taskinstance.py:441} INFO - ::group::Post task execution logs
[2024-06-27T12:55:06.137+0000] {taskinstance.py:2905} ERROR - Task failed with exception
Traceback (most recent call last):
  File "/home/airflow/.local/lib/python3.12/site-packages/airflow/models/taskinstance.py", line 465, in _execute_task
    result = _execute_callable(context=context, **execute_callable_kwargs)
             ^^^^^^^^^^^^^^^^^^^^^^^^^^^^^^^^^^^^^^^^^^^^^^^^^^^^^^^^^^^^^
  File "/home/airflow/.local/lib/python3.12/site-packages/airflow/models/taskinstance.py", line 432, in _execute_callable
    return execute_callable(context=context, **execute_callable_kwargs)
           ^^^^^^^^^^^^^^^^^^^^^^^^^^^^^^^^^^^^^^^^^^^^^^^^^^^^^^^^^^^^
  File "/home/airflow/.local/lib/python3.12/site-packages/airflow/models/baseoperator.py", line 400, in wrapper
    return func(self, *args, **kwargs)
           ^^^^^^^^^^^^^^^^^^^^^^^^^^^
  File "/home/airflow/.local/lib/python3.12/site-packages/airflow/operators/python.py", line 235, in execute
    return_value = self.execute_callable()
                   ^^^^^^^^^^^^^^^^^^^^^^^
  File "/home/airflow/.local/lib/python3.12/site-packages/airflow/operators/python.py", line 252, in execute_callable
    return self.python_callable(*self.op_args, **self.op_kwargs)
           ^^^^^^^^^^^^^^^^^^^^^^^^^^^^^^^^^^^^^^^^^^^^^^^^^^^^^
  File "/opt/airflow/dags/helper_functions.py", line 243, in alert_notif_skipped_api
    for run_id in run_ids:
                  ^^^^^^^
NameError: name 'run_ids' is not defined
[2024-06-27T12:55:06.148+0000] {taskinstance.py:1206} INFO - Marking task as UP_FOR_RETRY. dag_id=demo_dag_for_alerting_apis_final, task_id=skipped_due_to_data_unavailability, run_id=scheduled__2024-06-27T12:54:00+00:00, execution_date=20240627T125400, start_date=20240627T125505, end_date=20240627T125506
[2024-06-27T12:55:06.160+0000] {standard_task_runner.py:110} ERROR - Failed to execute job 4721 for task skipped_due_to_data_unavailability (name 'run_ids' is not defined; 4594)
[2024-06-27T12:55:06.193+0000] {local_task_job_runner.py:240} INFO - Task exited with return code 1
[2024-06-27T12:55:06.237+0000] {taskinstance.py:3498} INFO - 0 downstream tasks scheduled from follow-on schedule check
[2024-06-27T12:55:06.239+0000] {local_task_job_runner.py:222} INFO - ::endgroup::
